Workbook

Sheet 0 · Cover
A1: MES360° — WO-2026-0007 · Manual KPI Calculation
A3: Purpose | B3: Independent hand-calculation of every production KPI for the BETTI line on 28-07-2026, from the client's manually recorded data only. Used as the reference baseline against which the MES360 system output is compared.
A4: Source — production / stoppage / waste | B4: docs/recived from client/BETTI Production Line Stoppages and Waste Log 28072026.xlsx | C4: as received
A5: Source — machine rates | B5: docs/recived from client/Betti Production Line Production Rate.xlsx | C5: as received
A6: Source — product master | B6: docs/master data inventory/BB Item (3).xlsx + sdpf big betti production details.xlsx | C6: already loaded in MES360
A8: Factory | B8: SDPF — Saudi Detergent Powder Factory | C8: PoC factory
A9: Line | B9: PL-01 — Powder Packing Line 1 ("BETTI Production Line")
A10: Machines | B10: M1 Big Betti · M2 Checkweigher · M3 Cartomac · M4 Euro-Pack Robot · M5 Uni-tech Wrapping
A11: Product | B11: 10310064 — Alwatani Powder Detergent · Violet HF · 6 × 2 Kg Carton
A12: Production date | B12: 28-07-2026 | C12: Tuesday
A13: Production window | B13: 08:00 → 16:30 | C13: 510 minutes
A15: How to read this workbook | B15: Yellow cells are INPUTS transcribed from the client's files — nothing else is typed. Every white/grey cell is a live Excel formula. Change an input and every KPI recalculates.
A16: Sheet 1 · Inputs — Production | B16: Quantities produced and waste, exactly as logged.
A17: Sheet 2 · Inputs — Stoppages | B17: All 14 stoppage events, with duration recomputed from start/end.
A18: Sheet 3 · Inputs — Machine Rates | B18: The 5-run rate test, converted to ideal cycle times.
A19: Sheet 4 · Manual KPI | B19: The line OEE calculation — six scenarios, ISO 22400 and as-built.
A20: Sheet 5 · Per-Machine KPI | B20: The same calculation resolved to each machine.
A21: Sheet 6 · Downtime Pareto | B21: Loss ranking by category — the improvement shortlist.
A22: Sheet 7 · Manual vs System | B22: Side-by-side gap table. System column is filled by the verify script.
A23: Sheet 8 · Data Issues | B23: Contradictions found inside the client's own data — needs their answer.

Sheet 1 · Inputs-Production
A1: Inputs — Production, Waste & Product Master (yellow = transcribed from client file)
A3: # | B3: Item | C3: Value | D3: Unit | E3: Recorded at machine | F3: Note
A4: 1 | B4: Production date | C4: 2026-07-28 | F4: client log, cell E5
A5: 2 | B5: Production start | C5: 08:00 | F5: client log, cell E7
A6: 3 | B6: Production end | C6: 16:30 | F6: client log, cell E8
A7: 4 | B7: Quantity — Inner Carton (Duplex) | C7: 6720 | D7: piece | E7: M1 Big Betti Filling | F7: the 2 Kg retail pack
A8: 5 | B8: Quantity — Outer Carton | C8: 1120 | D8: piece | E8: M3 Cartomac | F8: 6 inner packs per outer carton
A9: 6 | B9: Quantity — FG Pallet | C9: 28 | D9: piece | E9: M4 Euro-Pack + M5 Uni-tech | F9: see Sheet 8 — conflicts with master data
A10: 7 | B10: Waste — Inner Carton (Duplex) | C10: 86 | D10: piece | E10: M1 Big Betti
A11: 8 | B11: Waste — Outer Carton | C11: 19 | D11: piece | E11: M3 Cartomac
A12: 9 | B12: Waste — Powder | C12: 300 | D12: kg | E12: M1 Big Betti | F12: material loss, not a unit reject
B14: PRODUCT MASTER (already in MES360)
B15: SKU / item number | C15: 10310064 | F15: BB Item (3).xlsx
B16: Inner packs per outer carton | C16: 6 | D16: pc/ctn | F16: BB Item — "PC IN CARTON"
B17: Outer cartons per pallet | C17: 32 | D17: ctn/pal | F17: BB Item — "Pallet"; BOM confirms 1/0.031262 = 32.0
B18: Powder per outer carton | C18: 12 | D18: kg/ctn | F18: BOM line 20300009 Al Watani HF Violet Powder
B19: Pack weight | C19: 2 | D19: kg | F19: 6 × 2 Kg
B20: BOM hourly machine target | C20: 325 | D20: ctn/h | F20: BOM "1 HR Machine Target" — the planned line rate
A22: Terminology: the client's "Inner Carton (Duplex)" is the individual 2 Kg consumer pack — BOM component 40330078 "Inner Carton Al Watani Violet 2 KG (EU Format)", 6 per outer case. 6720 ÷ 6 = 1120 outer cartons, which matches the logged outer-carton count exactly.

Sheet 2 · Inputs-Stoppages
A1: Inputs — Stoppage Log (duration is RECOMPUTED from start/end, not transcribed)
A3: # | B3: Machine | C3: Start | D3: End | E3: Duration (calc, min) | F3: Client stated | G3: Category | H3: Description | I3: Planned? | J3: Micro-stop (<5 min)
A4: 1 | B4: Big Betti | C4: 08:00 | D4: 09:45 | E4: =(VALUE(LEFT(D4,2))*60+VALUE(MID(D4,4,2)))-(VALUE(LEFT(C4,2))*60+VALUE(MID(C4,4,2))) | F4: 105 | G4: Mechanical | H4: Machine Synchronization | I4: =IF(G4="Break","PLANNED","unplanned") | J4: =IF(AND(E4<5,I4="unplanned"),"yes","")
A5: 2 | B5: Big Betti | C5: 09:50 | D5: 10:40 | E5: =(VALUE(LEFT(D5,2))*60+VALUE(MID(D5,4,2)))-(VALUE(LEFT(C5,2))*60+VALUE(MID(C5,4,2))) | F5: 50 | G5: Startup | H5: Machine Adjustments | I5: =IF(G5="Break","PLANNED","unplanned") | J5: =IF(AND(E5<5,I5="unplanned"),"yes","")
A6: 3 | B6: Big Betti | C6: 11:20 | D6: 11:37 | E6: =(VALUE(LEFT(D6,2))*60+VALUE(MID(D6,4,2)))-(VALUE(LEFT(C6,2))*60+VALUE(MID(C6,4,2))) | F6: 17 | G6: Mechanical | H6: Glue Leakage | I6: =IF(G6="Break","PLANNED","unplanned") | J6: =IF(AND(E6<5,I6="unplanned"),"yes","")
A7: 4 | B7: Big Betti | C7: 11:40 | D7: 11:42 | E7: =(VALUE(LEFT(D7,2))*60+VALUE(MID(D7,4,2)))-(VALUE(LEFT(C7,2))*60+VALUE(MID(C7,4,2))) | F7: 2 | G7: Mechanical | H7: Glue Removal | I7: =IF(G7="Break","PLANNED","unplanned") | J7: =IF(AND(E7<5,I7="unplanned"),"yes","")
A8: 5 | B8: Big Betti | C8: 12:00 | D8: 12:30 | E8: =(VALUE(LEFT(D8,2))*60+VALUE(MID(D8,4,2)))-(VALUE(LEFT(C8,2))*60+VALUE(MID(C8,4,2))) | F8: 30 | G8: Break | H8: Lunch Break | I8: =IF(G8="Break","PLANNED","unplanned") | J8: =IF(AND(E8<5,I8="unplanned"),"yes","")
A9: 6 | B9: Big Betti | C9: 12:38 | D9: 12:42 | E9: =(VALUE(LEFT(D9,2))*60+VALUE(MID(D9,4,2)))-(VALUE(LEFT(C9,2))*60+VALUE(MID(C9,4,2))) | F9: 4 | G9: Mechanical | H9: Rollers Conveyor Cleaning | I9: =IF(G9="Break","PLANNED","unplanned") | J9: =IF(AND(E9<5,I9="unplanned"),"yes","")
A10: 7 | B10: Big Betti | C10: 12:52 | D10: 12:57 | E10: =(VALUE(LEFT(D10,2))*60+VALUE(MID(D10,4,2)))-(VALUE(LEFT(C10,2))*60+VALUE(MID(C10,4,2))) | F10: 5 | G10: Packaging Material Shortage | H10: Packaging defected - Dulpex (Inner Carton) | I10: =IF(G10="Break","PLANNED","unplanned") | J10: =IF(AND(E10<5,I10="unplanned"),"yes","")
A11: 8 | B11: Big Betti | C11: 13:00 | D11: 13:04 | E11: =(VALUE(LEFT(D11,2))*60+VALUE(MID(D11,4,2)))-(VALUE(LEFT(C11,2))*60+VALUE(MID(C11,4,2))) | F11: 4 | G11: Powder Shortage | H11: No powder | I11: =IF(G11="Break","PLANNED","unplanned") | J11: =IF(AND(E11<5,I11="unplanned"),"yes","")
A12: 9 | B12: Big Betti | C12: 13:18 | D12: 13:26 | E12: =(VALUE(LEFT(D12,2))*60+VALUE(MID(D12,4,2)))-(VALUE(LEFT(C12,2))*60+VALUE(MID(C12,4,2))) | F12: 8 | G12: Mechanical | H12: Open Dulpex - Guide Adjustment | I12: =IF(G12="Break","PLANNED","unplanned") | J12: =IF(AND(E12<5,I12="unplanned"),"yes","")
A13: 10 | B13: Big Betti | C13: 13:38 | D13: 13:39 | E13: =(VALUE(LEFT(D13,2))*60+VALUE(MID(D13,4,2)))-(VALUE(LEFT(C13,2))*60+VALUE(MID(C13,4,2))) | F13: 1 | G13: Packaging Material Shortage | H13: No Pallet at Euro-Pack Robot | I13: =IF(G13="Break","PLANNED","unplanned") | J13: =IF(AND(E13<5,I13="unplanned"),"yes","")
A14: 11 | B14: Big Betti | C14: 13:40 | D14: 13:45 | E14: =(VALUE(LEFT(D14,2))*60+VALUE(MID(D14,4,2)))-(VALUE(LEFT(C14,2))*60+VALUE(MID(C14,4,2))) | F14: 5 | G14: Mechanical | H14: Rollers Conveyor Cleaning | I14: =IF(G14="Break","PLANNED","unplanned") | J14: =IF(AND(E14<5,I14="unplanned"),"yes","")
A15: 12 | B15: Big Betti | C15: 14:10 | D15: 14:52 | E15: =(VALUE(LEFT(D15,2))*60+VALUE(MID(D15,4,2)))-(VALUE(LEFT(C15,2))*60+VALUE(MID(C15,4,2))) | F15: 42 | G15: Mechanical | H15: Open Dulpex - Guide Adjustment | I15: =IF(G15="Break","PLANNED","unplanned") | J15: =IF(AND(E15<5,I15="unplanned"),"yes","")
... A17: 14 | B17: Big Betti | C17: 15:24 | D17: 15:28 | E17: =(VALUE(LEFT(D17,2))*60+VALUE(MID(D17,4,2)))-(VALUE(LEFT(C17,2))*60+VALUE(MID(C17,4,2))) | F17: 4 | G17: Mechanical | H17: Open Dulpex - Guide Adjustment | I17: =IF(G17="Break","PLANNED","unplanned") | J17: =IF(AND(E17<5,I17="unplanned"),"yes","")
B19: Total stoppage | E19: =SUM(E4:E17) | F19: min | H19: client's own total = 281 → must match
B20: of which PLANNED (break) | E20: =SUMIF(I4:I17,"PLANNED",E4:E17) | F20: min | H20: excluded from OEE availability loss (ISO 22400)
B21: of which UNPLANNED | E21: =SUMIF(I4:I17,"unplanned",E4:E17) | F21: min | H21: the availability loss
B22: Unplanned event count | E22: =COUNTIF(I4:I17,"unplanned") | F22: events | H22: drives MTBF / MTTR
B23: Micro-stops (<5 min) within unplanned | E23: =SUMIF(J4:J17,"yes",E4:E17) | F23: min | H23: ISO 22400 classes these as a PERFORMANCE loss, not availability
B24: Longest single stop | E24: =MAX(E4:E17) | F24: min | H24: stop #1, machine synchronization
A26: Every stoppage was logged by the client against machine "Big Betti", but the total is labelled "Betti Production Line" — so these are LINE stoppages: the packing line has no buffers, so a stop anywhere halts filling, cartoning, palletising and wrapping together. The KPIs below therefore treat the line as one unit, which is also how the client's own manual total works.

Sheet 3 · Inputs-Rates
A1: Inputs — Machine Rate Test, 28-07-2026 (client's "Production Rate" file, 5 runs)
A3: Run | B3: M1 Big Betti Filling (pack / min) | C3: M3 Cartomac (carton / min) | D3: M4 Palletising Robot (min / pallet) | E3: M5 Wrapping Machine (min / pallet) | G3: Derived ideal cycle time | H3: Value | I3: Unit | J3: How it is used
A4: 1 | B4: 50 | C4: 7 | D4: 3.5666667 | E4: 2.1 | G4: M1 Big Betti — per inner pack | H4: =60/'3 · Inputs-Rates'!$B$9 | I4: sec / pack | J4: ideal cycle time for the filling step
A5: 2 | B5: 50 | C5: 9 | D5: 3.9666667 | E5: 1.9333333 | G5: M1 Big Betti — per outer carton | H5: ='1 · Inputs-Production'!$C$16/'3 · Inputs-Rates'!$B$9 | I5: min / carton | J5: 6 packs make one carton
A6: 3 | B6: 50 | C6: 9 | D6: 3.6 | E6: 1.7833333 | G6: M3 Cartomac — per outer carton (best) | H6: =60/'3 · Inputs-Rates'!$C$9 | I6: sec / carton | J6: ideal cycle time for the cartoning step
A7: 4 | B7: 50 | C7: 9 | D7: 3.7333333 | E7: 1.8333333 | G7: M3 Cartomac — per outer carton (avg) | H7: =60/'3 · Inputs-Rates'!$C$10 | I7: sec / carton | J7: sensitivity check — scenario B
A8: 5 | B8: 50 | C8: 9 | D8: 3.8166667 | E8: 2.0166667 | G8: M4 Euro-Pack Robot — per pallet | H8: ='3 · Inputs-Rates'!$D$9*60 | I8: sec / pallet | J8: palletising step
A9: Best demonstrated | B9: =MAX(B4:B8) | C9: =MAX(C4:C8) | D9: =MIN(D4:D8) | E9: =MIN(E4:E8) | G9: M5 Uni-tech Wrapping — per pallet | H9: ='3 · Inputs-Rates'!$E$9*60 | I9: sec / pallet | J9: wrapping step
A10: Average of 5 runs | B10: =AVERAGE(B4:B8) | C10: =AVERAGE(C4:C8) | D10: =AVERAGE(D4:D8) | E10: =AVERAGE(E4:E8) | G10: BOM planned rate — per outer carton | H10: =60/'1 · Inputs-Production'!$C$20 | I10: min / carton | J10: the PLANNED rate (325 ctn/h) already in MES360 — scenario D
A12: ISO 22400 defines the OEE Performance denominator as the THEORETICAL BEST cycle time, so the headline scenario uses the best of the five runs. The average is carried as a sensitivity check. Note the two different rate concepts: 50 pack/min and 9 ctn/min are MACHINE instantaneous rates, while 325 ctn/h from the BOM is the PLANNED LINE rate that already includes an allowance for stops.

Sheet 4 · Manual KPI
A1: Manual KPI Calculation — Line level, output unit = OUTER CARTON
B3: STEP 1 — TIME MODEL
B4: Production start | C4: =VALUE(LEFT('1 · Inputs-Production'!$C$5,2))*60+VALUE(MID('1 · Inputs-Production'!$C$5,4,2)) | D4: min | E4: 480 = 08:00 expressed as minutes from midnight (read from Sheet 1)
B5: Production end | C5: =VALUE(LEFT('1 · Inputs-Production'!$C$6,2))*60+VALUE(MID('1 · Inputs-Production'!$C$6,4,2)) | D5: min | E5: 990 = 16:30 (read from Sheet 1)
B6: Scheduled window (= end − start) | C6: =C5-C4 | D6: min | E6: the calendar time the line was manned
B7: Planned stops (lunch break) | C7: ='2 · Inputs-Stoppages'!$E$20 | D7: min | E7: ISO 22400: removed from the denominator
B8: Planned Production Time PPT (= window − planned) | C8: =C6-C7 | D8: min | E8: ★ the OEE availability denominator
B9: Unplanned downtime | C9: ='2 · Inputs-Stoppages'!$E$21 | D9: min | E9: the availability loss
B10: Run time (= PPT − unplanned) | C10: =C8-C9 | D10: min | E10: ★ the time the line actually produced
B12: STEP 2 — COUNTS (in outer cartons, the SKU base unit)
B13: Good outer cartons | C13: ='1 · Inputs-Production'!$C$8 | D13: ctn | E13: as logged
B14: Scrap outer cartons | C14: ='1 · Inputs-Production'!$C$11 | D14: ctn | E14: as logged
B15: Total outer cartons (= good + scrap) | C15: =C13+C14 | D15: ctn | E15: ★ the OEE Performance/Quality numerator base
B16: Cross-check: inner ÷ 6 | C16: ='1 · Inputs-Production'!$C$7/'1 · Inputs-Production'!$C$16 | D16: ctn | E16: must equal good outer cartons
B17: Good inner packs | C17: ='1 · Inputs-Production'!$C$7 | D17: pack
B18: Scrap inner packs | C18: ='1 · Inputs-Production'!$C$10 | D18: pack
B19: Good pallets | C19: ='1 · Inputs-Production'!$C$9 | D19: pallet | E19: see Sheet 8 — inconsistent with 32 ctn/pallet
B20: Powder waste | C20: ='1 · Inputs-Production'!$C$12 | D20: kg | E20: material loss — NOT a unit reject, see below
B22: STEP 3 — OEE SCENARIOS (A × P × Q)
B23: → see sheet "4b · OEE Scenarios" for the six scenarios
B25: STEP 4 — SUPPORTING KPIs
B26: Availability | C26: ='4b · OEE Scenarios'!$G$4 | D26: % | E26: run time ÷ PPT — scenario A
B27: Performance | C27: ='4b · OEE Scenarios'!$H$4 | D27: % | E27: ideal run ÷ run time — scenario A
B28: Quality | C28: ='4b · OEE Scenarios'!$I$4 | D28: % | E28: good ÷ total cartons
B29: OEE (schedule-based) | C29: ='4b · OEE Scenarios'!$J$4 | D29: % | E29: ★ A × P × Q — the headline number
B30: Availability (time-based, AT-OEE) | C30: =('4 · Manual KPI'!$C$6-'2 · Inputs-Stoppages'!$E$21)/'4 · Manual KPI'!$C$6*100 | D30: % | E30: uptime ÷ full span — ignores the plan, machine-centric
B31: OEE (time-based, AT-OEE) | C31: =C30/100*'4b · OEE Scenarios'!$H$4/100*'4b · OEE Scenarios'!$I$4/100*100 | D31: % | E31: the AT-OEE variant the platform reports alongside
B32: First-Pass Yield (carton) | C32: ='4 · Manual KPI'!$C$13/'4 · Manual KPI'!$C$15*100 | D32: % | E32: same as Quality here — one pass, no rework
B33: Scrap rate (carton) | C33: ='4 · Manual KPI'!$C$14/'4 · Manual KPI'!$C$15*100 | D33: %
B34: Scrap rate (inner pack) | C34: ='1 · Inputs-Production'!$C$10/('1 · Inputs-Production'!$C$7+'1 · Inputs-Production'!$C$10)*100 | D34: % | E34: the filling step rejects more units than the cartoning step
B35: Material yield (powder) | C35: ='4 · Manual KPI'!$C$13*'1 · Inputs-Production'!$C$18/('4 · Manual KPI'!$C$13*'1 · Inputs-Production'!$C$18+'1 · Inputs-Production'!$C$12)*100 | D35: % | E35: powder into good product ÷ powder issued. A MATERIAL KPI — deliberately NOT folded into OEE Quality, which is unit-based.
B36: Throughput while running | C36: ='4 · Manual KPI'!$C$13/'4 · Manual KPI'!$C$10*60 | D36: ctn / h | E36: the line's real demonstrated output rate
B37: Throughput over the full span | C37: ='4 · Manual KPI'!$C$13/'4 · Manual KPI'!$C$6*60 | D37: ctn / h | E37: what the plant actually delivered per manned hour
B38: Attainment vs BOM target | C38: ='4 · Manual KPI'!$C$13/'4 · Manual KPI'!$C$6*60/'1 · Inputs-Production'!$C$20*100 | D38: % | E38: against the 325 ctn/h planned rate
B39: MTBF — mean run time between stops | C39: ='4 · Manual KPI'!$C$10/'2 · Inputs-Stoppages'!$E$22 | D39: min | E39: run time ÷ unplanned stop count
B40: MTTR — mean stop duration | C40: ='2 · Inputs-Stoppages'!$E$21/'2 · Inputs-Stoppages'!$E$22 | D40: min | E40: unplanned minutes ÷ unplanned stop count
B41: Micro-stop minutes (<5 min) | C41: ='2 · Inputs-Stoppages'!$E$23 | D41: min | E41: ISO 22400 classes these as a performance loss; the client logged them as downtime
B43: STEP 5 — SIX BIG LOSSES (against PPT)
B44: Loss bucket | C44: Minutes | D44: % of PPT
B45: Availability loss — unplanned downtime | C45: ='2 · Inputs-Stoppages'!$E$21 | D45: ='2 · Inputs-Stoppages'!$E$21/'4 · Manual KPI'!$C$8*100
...

Sheet 4b · OEE Scenarios
A1: OEE Scenarios — same time model, different ideal-cycle-time assumption
A3: # | B3: Scenario | C3: PPT (min) | D3: Unplanned (min) | E3: Run time (min) | F3: Ideal run (min) | G3: A | H3: P | I3: Q | J3: OEE | K3: What the assumption means
A4: A | B4: ISO 22400 · ideal = Cartomac best demonstrated (9 ctn/min) | C4: ='4 · Manual KPI'!$C$8 | D4: ='2 · Inputs-Stoppages'!$E$21 | E4: =C4-D4 | F4: =(1/'3 · Inputs-Rates'!$C$9)*'4 · Manual KPI'!$C$15 | G4: =E4/C4*100 | H4: =MIN(F4/E4*100,100) | I4: ='4 · Manual KPI'!$C$13/'4 · Manual KPI'!$C$15*100 | J4: =G4/100*H4/100*I4/100*100 | K4: Headline. Theoretical best from the client's own rate test.
A5: B | B5: ISO 22400 · ideal = Cartomac 5-run average (8.6 ctn/min) | C5: ='4 · Manual KPI'!$C$8 | D5: ='2 · Inputs-Stoppages'!$E$21 | E5: =C5-D5 | F5: =(1/'3 · Inputs-Rates'!$C$10)*'4 · Manual KPI'!$C$15 | G5: =E5/C5*100 | H5: =MIN(F5/E5*100,100) | I5: ='4 · Manual KPI'!$C$13/'4 · Manual KPI'!$C$15*100 | J5: =G5/100*H5/100*I5/100*100 | K5: Sensitivity — how much the answer moves on rate choice.
A6: C | B6: ISO 22400 · ideal = Big Betti 50 pack/min (= 8.33 ctn/min) | C6: ='4 · Manual KPI'!$C$8 | D6: ='2 · Inputs-Stoppages'!$E$21 | E6: =C6-D6 | F6: =('1 · Inputs-Production'!$C$16/'3 · Inputs-Rates'!$B$9)*'4 · Manual KPI'!$C$15 | G6: =E6/C6*100 | H6: =MIN(F6/E6*100,100) | I6: ='4 · Manual KPI'!$C$13/'4 · Manual KPI'!$C$15*100 | J6: =G6/100*H6/100*I6/100*100 | K6: Filling machine as the pacing constraint instead of cartoning.
A7: D | B7: ISO 22400 · ideal = BOM planned target 325 ctn/h (5.42 ctn/min) | C7: ='4 · Manual KPI'!$C$8 | D7: ='2 · Inputs-Stoppages'!$E$21 | E7: =C7-D7 | F7: =(60/'1 · Inputs-Production'!$C$20)*'4 · Manual KPI'!$C$15 | G7: =E7/C7*100 | H7: =MIN(F7/E7*100,100) | I7: ='4 · Manual KPI'!$C$13/'4 · Manual KPI'!$C$15*100 | J7: =G7/100*H7/100*I7/100*100 | K7: The rate already loaded in MES360. It is a PLANNED rate, so it flatters Performance — not an ISO ideal cycle time.
A8: E | B8: MES360 as-built · PPT = full 510 min span · ideal = 9 ctn/min | C8: ='4 · Manual KPI'!$C$6 | D8: ='2 · Inputs-Stoppages'!$E$21 | E8: =C8-D8 | F8: =(1/'3 · Inputs-Rates'!$C$9)*'4 · Manual KPI'!$C$15 | G8: =E8/C8*100 | H8: =MIN(F8/E8*100,100) | I8: ='4 · Manual KPI'!$C$13/'4 · Manual KPI'!$C$15*100 | J8: =G8/100*H8/100*I8/100*100 | K8: ★ What the system currently computes: kpi.service.joPpt/woChild does NOT remove the planned break from PPT.
A9: F | B9: MES360 as-built · PPT = full 510 min span · ideal = 325 ctn/h | C9: ='4 · Manual KPI'!$C$6 | D9: ='2 · Inputs-Stoppages'!$E$21 | E9: =C9-D9 | F9: =(60/'1 · Inputs-Production'!$C$20)*'4 · Manual KPI'!$C$15 | G9: =E9/C9*100 | H9: =MIN(F9/E9*100,100) | I9: ='4 · Manual KPI'!$C$13/'4 · Manual KPI'!$C$15*100 | J9: =G9/100*H9/100*I9/100*100 | K9: ★ What the system computes TODAY, before the cycle-time fix.
A11: Scenario A is the reference the system is graded against. The gap between A and E is caused by the planned-break handling; the gap between A and F additionally includes the wrong cycle time currently loaded in MachineCycleTime. Both are itemised in Sheet 7.

Sheet 5 · Per-Machine KPI
A1: Per-Machine KPI — every machine sees the same line stoppage window
A3: Code | B3: Machine | C3: Step | D3: Output unit | E3: Good | F3: Scrap | G3: Total | H3: Ideal cycle (sec/unit) | I3: A | J3: P | K3: Q | L3: OEE | M3: Reading
A4: M1 | B4: Big Betti | C4: Filling | D4: INNER | E4: ='1 · Inputs-Production'!$C$7 | F4: ='1 · Inputs-Production'!$C$10 | G4: =E4+F4 | H4: =60/'3 · Inputs-Rates'!$B$9 | I4: ='4 · Manual KPI'!$C$10/'4 · Manual KPI'!$C$8*100 | J4: =MIN(H4/60*G4/'4 · Manual KPI'!$C$10*100,100) | K4: =IF(G4=0,0,E4/G4*100) | L4: =I4/100*J4/100*K4/100*100 | M4: The line's pacing constraint. Its P is the honest speed-loss signal.
A5: M3 | B5: Cartomac | C5: Cartoning | D5: CARTON | E5: ='1 · Inputs-Production'!$C$8 | F5: ='1 · Inputs-Production'!$C$11 | G5: =E5+F5 | H5: =60/'3 · Inputs-Rates'!$C$9 | I5: ='4 · Manual KPI'!$C$10/'4 · Manual KPI'!$C$8*100 | J5: =MIN(H5/60*G5/'4 · Manual KPI'!$C$10*100,100) | K5: =IF(G5=0,0,E5/G5*100) | L5: =I5/100*J5/100*K5/100*100 | M5: Matches the line calculation, since carton is the SKU base unit.
A6: M4 | B6: Euro-Pack Robot | C6: Palletising | D6: PALLET | E6: ='1 · Inputs-Production'!$C$9 | F6: =0 | G6: =E6+F6 | H6: ='3 · Inputs-Rates'!$D$9*60 | I6: ='4 · Manual KPI'!$C$10/'4 · Manual KPI'!$C$8*100 | J6: =MIN(H6/60*G6/'4 · Manual KPI'!$C$10*100,100) | K6: =IF(G6=0,0,E6/G6*100) | L6: =I6/100*J6/100*K6/100*100 | M6: Low P is expected — the robot is not the constraint and idles between pallets. Do NOT read this as a robot problem.
A7: M5 | B7: Uni-tech Wrapping | C7: Wrapping | D7: PALLET | E7: ='1 · Inputs-Production'!$C$9 | F7: =0 | G7: =E7+F7 | H7: ='3 · Inputs-Rates'!$E$9*60 | I7: ='4 · Manual KPI'!$C$10/'4 · Manual KPI'!$C$8*100 | J7: =MIN(H7/60*G7/'4 · Manual KPI'!$C$10*100,100) | K7: =IF(G7=0,0,E7/G7*100) | L7: =I7/100*J7/100*K7/100*100 | M7: Same caveat as M4, more so — the wrapper is the least loaded machine on the line.
A9: Availability is identical for all four machines because the line has no buffers — the client's own log records one stoppage stream for the whole line. Performance differs only because each machine has its own ideal cycle time and output unit. The LINE OEE is the M3/Cartomac row, because the outer carton is the SKU base unit and therefore the unit the WO is measured in.

Sheet 6 · Downtime Pareto
A1: Downtime Pareto — where the 251 unplanned minutes went
A3: # | B3: Category (as logged by client) | C3: Minutes | D3: Events | E3: % of unplanned | F3: % of PPT | G3: Cumulative % | H3: Action
A4: 1 | B4: Mechanical | C4: =SUMIFS('2 · Inputs-Stoppages'!$E$4:$E$17,'2 · Inputs-Stoppages'!$G$4:$G$17,B4,'2 · Inputs-Stoppages'!$I$4:$I$17,"unplanned") | D4: =COUNTIFS('2 · Inputs-Stoppages'!$G$4:$G$17,B4,'2 · Inputs-Stoppages'!$I$4:$I$17,"unplanned") | E4: =C4/'2 · Inputs-Stoppages'!$E$21*100 | F4: =C4/'4 · Manual KPI'!$C$8*100 | G4: =SUM($C$4:C4)/'2 · Inputs-Stoppages'!$E$21*100 | H4: 8 events, 187 min. Two repeat offenders dominate: "Open Dulpex – Guide Adjustment" (3 events, 54 min) and the 105-min synchronisation at start-up. Guide-setting SOP + a start-up checklist are the highest-value fixes.
A5: 2 | B5: Startup | C5: =SUMIFS('2 · Inputs-Stoppages'!$E$4:$E$17,'2 · Inputs-Stoppages'!$G$4:$G$17,B5,'2 · Inputs-Stoppages'!$I$4:$I$17,"unplanned") | D5: =COUNTIFS('2 · Inputs-Stoppages'!$G$4:$G$17,B5,'2 · Inputs-Stoppages'!$I$4:$I$17,"unplanned") | E5: =C5/'2 · Inputs-Stoppages'!$E$21*100 | F5: =C5/'4 · Manual KPI'!$C$8*100 | G5: =SUM($C$4:C5)/'2 · Inputs-Stoppages'!$E$21*100 | H5: One 50-min machine-adjustment block right after the synchronisation stop. Together with stop #1 this means the line lost 155 of its first 160 minutes.
A6: 3 | B6: Powder Shortage | C6: =SUMIFS('2 · Inputs-Stoppages'!$E$4:$E$17,'2 · Inputs-Stoppages'!$G$4:$G$17,B6,'2 · Inputs-Stoppages'!$I$4:$I$17,"unplanned") | D6: =COUNTIFS('2 · Inputs-Stoppages'!$G$4:$G$17,B6,'2 · Inputs-Stoppages'!$I$4:$I$17,"unplanned") | E6: =C6/'2 · Inputs-Stoppages'!$E$21*100 | F6: =C6/'4 · Manual KPI'!$C$8*100 | G6: =SUM($C$4:C6)/'2 · Inputs-Stoppages'!$E$21*100 | H6: 2 × 4 min. Small, but it is a material-supply signal — worth trending.
A7: 4 | B7: Packaging Material Shortage | C7: =SUMIFS('2 · Inputs-Stoppages'!$E$4:$E$17,'2 · Inputs-Stoppages'!$G$4:$G$17,B7,'2 · Inputs-Stoppages'!$I$4:$I$17,"unplanned") | D7: =COUNTIFS('2 · Inputs-Stoppages'!$G$4:$G$17,B7,'2 · Inputs-Stoppages'!$I$4:$I$17,"unplanned") | E7: =C7/'2 · Inputs-Stoppages'!$E$21*100 | F7: =C7/'4 · Manual KPI'!$C$8*100 | G7: =SUM($C$4:C7)/'2 · Inputs-Stoppages'!$E$21*100 | H7: 5 min defective duplex + 1 min no pallet at the robot. Minor.
B8: TOTAL unplanned | C8: =SUM(C4:C7) | D8: =SUM(D4:D7)
B10: Planned stop (excluded from the Pareto above) | C10: ='2 · Inputs-Stoppages'!$E$20 | H10: Lunch break 12:00–12:30. Removed from PPT under ISO 22400, so it is not an availability loss.
A12: Repeat-offender view: "Open Dulpex – Guide Adjustment" occurs 3× (8 + 42 + 4 = 54 min) and "Rollers Conveyor Cleaning" 2× (4 + 5 = 9 min) and "No powder" 2× (8 min). Recurrence, not duration, is what a corrective action should target.

Sheet 7 · Manual vs System
A1: Manual vs MES360 — measured 31-07-2026 against the live system
A2: The MES360 column was MEASURED, not predicted: WO-2026-0007 was loaded into the live database and prisma/verify-wo-2026-0007.ts recomputed every KPI through the real KpiService/OEEService code path. Result: 10 of 18 comparable KPIs match exactly, and ALL 8 gaps trace to one root cause — G-01, planned stops left inside Planned Production Time. Re-run the script to refresh this column.
A4: # | B4: KPI | C4: Manual (this workbook) | D4: MES360 (measured) | E4: Gap | F4: Status | G4: Cause of the gap
A5: 1 | B5: Scheduled window (min) | C5: ='4 · Manual KPI'!$C$6 | D5: 510 | E5: =IF(D5="","",D5-C5) | F5: =IF(D5="","—",IF(ABS(D5-C5)<0.05,"MATCH","GAP")) | G5: Both read actualStart → actualEnd on the WO.
A6: 2 | B6: Planned stop minutes | C6: ='2 · Inputs-Stoppages'!$E$20 | D6: 30 | E6: =IF(D6="","",D6-C6) | F6: =IF(D6="","—",IF(ABS(D6-C6)<0.05,"MATCH","GAP")) | G6: System flags the break isPlanned=true, affectsOEE=false.
A7: 3 | B7: Unplanned downtime (min) | C7: ='2 · Inputs-Stoppages'!$E$21 | D7: 251 | E7: =IF(D7="","",D7-C7) | F7: =IF(D7="","—",IF(ABS(D7-C7)<0.05,"MATCH","GAP")) | G7: Sum of the 13 unplanned DowntimeEvent rows.
A8: 4 | B8: Planned Production Time (min) | C8: ='4 · Manual KPI'!$C$8 | D8: 510 | E8: =IF(D8="","",D8-C8) | F8: =IF(D8="","—",IF(ABS(D8-C8)<0.05,"MATCH","GAP")) | G8: ★ ROOT CAUSE (G-01). kpi.service.woChild() sets PPT = the full actualStart→actualEnd span and does not subtract planned stops, so the 30-min break stays in the denominator. ISO 22400 requires 480. Every gap below flows from this one.
A9: 5 | B9: Run time (min) | C9: ='4 · Manual KPI'!$C$10 | D9: 259 | E9: =IF(D9="","",D9-C9) | F9: =IF(D9="","—",IF(ABS(D9-C9)<0.05,"MATCH","GAP")) | G9: Consequence of G-01: 510 − 251 instead of 480 − 251.
A10: 6 | B10: Availability % | C10: ='4 · Manual KPI'!$C$26 | D10: 50.8 | E10: =IF(D10="","",D10-C10) | F10: =IF(D10="","—",IF(ABS(D10-C10)<0.05,"MATCH","GAP")) | G10: Consequence of G-01: 259/510 instead of 229/480.
A11: 7 | B11: Performance % | C11: ='4 · Manual KPI'!$C$27 | D11: 48.9 | E11: =IF(D11="","",D11-C11) | F11: =IF(D11="","—",IF(ABS(D11-C11)<0.05,"MATCH","GAP")) | G11: Consequence of G-01 — the SAME ideal run of 126.6 min divided by the inflated 259 run minutes instead of 229. NOT clamped at 100%, because the WO carries the measured 6.67 s/carton cycle time.
A12: 8 | B12: Quality % | C12: ='4 · Manual KPI'!$C$28 | D12: 98.3 | E12: =IF(D12="","",D12-C12) | F12: =IF(D12="","—",IF(ABS(D12-C12)<0.05,"MATCH","GAP")) | G12: Matches — same good/total.
A13: 9 | B13: OEE (schedule-based) % | C13: ='4 · Manual KPI'!$C$29 | D13: 24.4 | E13: =IF(D13="","",D13-C13) | F13: =IF(D13="","—",IF(ABS(D13-C13)<0.05,"MATCH","GAP")) | G13: Product of the A and P gaps above.
A14: 10 | B14: OEE (time-based / AT-OEE) % | C14: ='4 · Manual KPI'!$C$31 | D14: 24.4 | E14: =IF(D14="","",D14-C14) | F14: =IF(D14="","—",IF(ABS(D14-C14)<0.05,"MATCH","GAP")) | G14: AT-OEE is meant to be plan-independent, but it reuses P — so it inherits the G-01 distortion through the Performance term. Worth noting: its availability term (50.8%) is correct.
A15: 11 | B15: First-Pass Yield % | C15: ='4 · Manual KPI'!$C$32 | D15: 98.33 | E15: =IF(D15="","",D15-C15) | F15: =IF(D15="","—",IF(ABS(D15-C15)<0.05,"MATCH","GAP")) | G15: Matches exactly.
A16: 12 | B16: Scrap rate % | C16: ='4 · Manual KPI'!$C$33 | D16: 1.67 | E16: =IF(D16="","",D16-C16) | F16: =IF(D16="","—",IF(ABS(D16-C16)<0.05,"MATCH","GAP")) | G16: Matches exactly.
A17: 13 | B17: Good quantity (carton) | C17: ='4 · Manual KPI'!$C$13 | D17: 1120 | E17: =IF(D17="","",D17-C17) | F17: =IF(D17="","—",IF(ABS(D17-C17)<0.05,"MATCH","GAP")) | G17: Matches exactly.
A18: 14 | B18: Scrap quantity (carton) | C18: ='4 · Manual KPI'!$C$14 | D18: 19 | E18: =IF(D18="","",D18-C18) | F18: =IF(D18="","—",IF(ABS(D18-C18)<0.05,"MATCH","GAP")) | G18: Matches exactly.
A19: 15 | B19: Throughput while running (ctn/h) | C19: ='4 · Manual KPI'!$C$36 | D19: 259.46 | E19: =IF(D19="","",D19-C19) | F19: =IF(D19="","—",IF(ABS(D19-C19)<0.05,"MATCH","GAP")) | G19: Consequence of G-01 — 1120/259 instead of 1120/229.
A20: 16 | B20: MTBF (min) | C20: ='4 · Manual KPI'!$C$39 | D20: 19.92 | E20: =IF(D20="","",D20-C20) | F20: =IF(D20="","—",IF(ABS(D20-C20)<0.05,"MATCH","GAP")) | G20: Consequence of G-01 — run time 259/13 instead of 229/13. (The maintenance module computes MTBF from MaintenanceWO failures, a different definition by design.)
A21: 17 | B21: MTTR (min) | C21: ='4 · Manual KPI'!$C$40 | D21: 19.31 | E21: =IF(D21="","",D21-C21) | F21: =IF(D21="","—",IF(ABS(D21-C21)<0.05,"MATCH","GAP")) | G21: Matches — independent of PPT.
A22: 18 | B22: Material yield % | C22: ='4 · Manual KPI'!$C$35 | D22: 97.82 | E22: =IF(D22="","",D22-C22) | F22: =IF(D22="","—",IF(ABS(D22-C22)<0.05,"MATCH","GAP")) | G22: Matches — read from the MaterialConsumption variance (13 440 planned vs 13 740 actual kg).
A23: 19 | B23: Energy ratio (kWh / carton) | E23: =IF(D23="","",D23-C23) | F23: =IF(D23="","—",IF(ABS(D23-C23)<0.05,"MATCH","GAP")) | G23: No value: the client's manual log carries no meter readings, so no EnergyReading rows are tagged to this order. The endpoint returns an empty set correctly; the KPI populates once the line meters stream against a live work order.

Sheet 8 · Data Issues
A1: Contradictions inside the client's own data — needs an answer before Sunday
A3: # | B3: Where | C3: What was found | D3: Impact on the KPIs | E3: Question for the client | F3: Severity
A4: 1 | B4: Pallet count | C4: 1120 outer cartons ÷ 32 cartons/pallet = 35 pallets, but 28 were logged. 28 pallets × 32 = 896 cartons — 224 cartons short. The logged numbers only reconcile at 40 cartons/pallet. | D4: Pallet-level output, the M4/M5 machine KPIs and the pallet/stretch-film BOM consumption are all affected. Carton- and inner-level KPIs are unaffected. | E4: Is the Violet 6×2 Kg pallet pattern 32 or 40 cartons? If 32, were 7 pallets left part-built at shift end (work in progress)? | F4: HIGH
A5: 2 | B5: Pallet count — master data | C5: BB Item (3).xlsx says 32/pallet for 10310064, and the BOM agrees (1 ÷ 0.03126154 = 32.0). But seed-ncc-master.ts hard-codes 50 for every SKU, while seed-bb-master.ts reads the file correctly. | D5: Whichever seed last ran decides the number the system uses. If seed-ncc-master ran last, the system believes 50 cartons/pallet — wrong against the client's own master file. | E5: Confirm 32, then re-run seed-bb-master so the file value wins. | F5: HIGH
A6: 3 | B6: Powder waste | C6: 300 kg logged. Scrapped inner packs account for 86 × 2 kg = 172 kg; scrapped outer cartons for 19 × 12 kg = 228 kg. The three figures cannot all be independent — 228 + 172 already exceeds 300. | D6: Material yield is 97.8% if the 300 kg is the complete powder loss, but double-counted if the scrapped units are also inside it. OEE Quality is unaffected either way (it is unit-based). | E6: Is the 300 kg the TOTAL powder loss (including powder inside scrapped packs), or only spillage on top of them? | F6: MEDIUM
A7: 4 | B7: Stoppage attribution | C7: All 14 rows name "Big Betti", yet three descriptions point elsewhere: "No Pallet at Euro-Pack Robot" (M4), "Packaging defected – Dulpex" (inner-carton feed) and the glue events (both M1 and M3 have glue systems). | D7: Line OEE is correct either way. Per-machine Pareto and MTBF attribution are not — every minute currently lands on M1. | E7: Should stoppages be logged against the machine that FAILED, or against the line? MES360 supports both; per-machine is far more useful for maintenance. | F7: MEDIUM
A8: 5 | B8: Stop #1 at 08:00 | C8: The first stoppage starts at exactly the production start time and runs 105 min. Combined with stop #2 (50 min), the line lost 155 of its first 160 minutes. | D8: Availability drops from a would-be 79% to 47.7%. Whether this is production time at all is a definition question. | E8: Should start-up synchronisation be treated as production time (availability loss), or as planned set-up excluded from PPT like a changeover? | F8: MEDIUM
A9: 6 | B9: Cycle times in MES360 | C9: MachineCycleTime for this SKU is seeded at 31 s/inner (M1) and 25 s/carton (M3). The client's rate test measures 1.20 s/inner and 6.67 s/carton — 25.8× and 3.75× faster. | D9: Performance is computed against a denominator that is far too slow, so it saturates at the 100% clamp and OEE collapses to A × Q. This is the single largest source of system-vs-manual gap. | E9: Confirm the measured rates are the ones to load as ideal cycle times (this is what the rate file appears to be for). | F9: HIGH
A10: 7 | B10: Rate test vs pallet math | C10: The rate file's own header says "32 Cartons per Pallet", which contradicts the 40 implied by the production log on the same day. | D10: Same as row 1 — this is corroborating evidence that 32 is the intended pattern and the 28-pallet figure is the outlier. | E10: Included in question 1. | F10: INFO
A11: 8 | B11: Micro-stops | C11: 5 of the 13 unplanned stops are under 5 minutes (19 min total). ISO 22400 classes sub-5-minute interruptions as a PERFORMANCE loss, not an availability loss. | D11: Moving them would raise Availability to 50.0% and lower Performance correspondingly. OEE is almost unchanged — it only shifts which bucket gets the blame. | E11: Keep logging them as downtime (recommended — it is more honest and MES360 has a MICRO_STOP reason code for exactly this), or reclassify? | F11: LOW
